<?xml version="1.0" ?>
<robot name="vcr" xmlns:xacro="http://ros.org/wiki/xacro">
  <xacro:include filename="$(find vcr_description)/urdf/common_properties.xacro"/>
  <xacro:include filename="$(find vcr_description)/urdf/vcr.gazebo.xacro"/>

  <!-- <xacro:property name="r200_cam_rgb_px" value="0.005"/>
  <xacro:property name="r200_cam_rgb_py" value="0.018"/>
  <xacro:property name="r200_cam_rgb_pz" value="0.013"/>
  <xacro:property name="r200_cam_depth_offset" value="0.01"/> -->

  <link name="base_footprint"/>

  <joint name="base_joint" type="fixed">
    <parent link="base_footprint"/>
    <child link="base_link" />
    <origin xyz="0 0 0" rpy="0 0 0"/>
  </joint>

  <link name="base_link">
    <visual>
      <origin rpy="0 0 1.5707" xyz="0 0 -0.0735"/>
      <geometry>
        <mesh filename="package://vcr_description/meshes/bases/base.dae" scale="1 1 1"/>
      </geometry>
      <material name="light_black"/>
    </visual>

    <!-- <collision>
      <origin xyz="0 0 0.01" rpy="0 0 0"/>
      <geometry>
        <cylinder length="0.025" radius="0.03"/>
      </geometry>
    </collision> -->

    <collision name="collision_chassis1">
      <origin rpy="0 0 0" xyz="0 0 -0.02"/>
      <geometry>
       <cylinder length="0.005" radius="0.125"/> 
      </geometry>
    </collision>

    <collision name="collision_chassis2">
      <origin rpy="0 0 0" xyz="0 0 0.02"/>
      <geometry>
       <cylinder length="0.005" radius="0.08"/> 
      </geometry>
    </collision>

    <inertial>
      <mass value="0.5"/>
      <origin rpy="0 0 0" xyz="0 0 0"/>
       <inertia ixx="0.001" ixy="0.0" ixz="0.0"
               iyy="0.001" iyz="0.0"
               izz="0.001" />
    </inertial>
  </link>

<!-- Left Wheel -->

   <joint name="wheel_left_joint" type="continuous">
    <parent link="base_link"/>
    <child link="wheel_left_link"/>
    <origin xyz="0 0.09 -0.03" rpy="0 0 0"/>
    <axis rpy="0 0 0" xyz="0 1 0"/>
    <limit effort="100" velocity="100"/>
    <joint_properties damping="0.5" friction="0.5"/>
  </joint>

  <link name="wheel_left_link">
    <visual>
      <origin rpy="0 1.5707 1.5707" xyz="0 0 0"/>
      <geometry>
        <mesh filename="package://vcr_description/meshes/wheels/wheel.dae" scale="1 1 1"/>
      </geometry>
      <material name="dark"/>
    </visual>

    <collision>
      <origin rpy="0 1.5707 1.5707" xyz="0 0 0"/>
      <geometry>
        <cylinder length="0.025" radius="0.03"/>
      </geometry>
    </collision>

    <inertial>
      <mass value="0.2"/>
      <origin rpy="0 1.5707 1.5707" xyz="0 0 0"/>
       <inertia ixx="5.541667e-5" ixy="0.0" ixz="0.0"
               iyy="5.541667e-5" iyz="0.0"
               izz="9e-5" />
    </inertial>
  </link>

<!-- Right Wheel -->

  <joint name="wheel_right_joint" type="continuous">
    <parent link="base_link"/>
    <child link="wheel_right_link"/>
    <origin xyz="0 -0.09 -0.03" rpy="0 0 0"/>
    <axis rpy="0 0 0" xyz="0 1 0"/>
    <limit effort="100" velocity="100"/>
    <joint_properties damping="0.5" friction="0.5"/>
  </joint>

  <link name="wheel_right_link">
    <visual>
      <origin rpy="0 1.5707 1.5707" xyz="0 0 0"/>
      <geometry>
        <mesh filename="package://vcr_description/meshes/wheels/wheel.dae" scale="1 1 1"/>
      </geometry>
      <material name="dark"/>
    </visual>

    <collision>
      <origin rpy="0 1.5707 1.5707" xyz="0 0 0"/>
      <geometry>
        <cylinder length="0.025" radius="0.03"/>
      </geometry>
    </collision>

    <inertial>
      <mass value="0.2"/>
      <origin rpy="0 1.5707 1.5707" xyz="0 0 0"/>
      <inertia ixx="5.541667e-5" ixy="0.0" ixz="0.0"
               iyy="5.541667e-5" iyz="0.0"
               izz="9e-5" />
    </inertial>
  </link>

<!-- Motor  -->
  <joint name="motor_left_joint" type="fixed">
    <origin rpy="0 0 0" xyz="0 0.06 -0.03"/>
    <child link="motor_left_link"/>
    <parent link="base_link"/>
  </joint>

  <link name="motor_left_link">.005
    <inertial>.005
      <mass value="0.3"/>.005
      <origin rpy="0 1.5707 1.5707" xyz="0 0 0"/>
      <inertia ixx="9.75e-5" ixy="0.0" ixz="0.0"
               iyy="9.75e-5" iyz="0.0"
               izz="1.5e-5" />
    </inertial>

    <collision>
      <origin rpy="0 1.5707 1.5707" xyz="0 0 0"/>
      <geometry>
          <cylinder length="0.06" radius="0.01"/>
      </geometry>
    </collision>

    <visual>
      <origin rpy="0 1.5707 1.5707" xyz="0 0 0"/>
      <geometry>
        <cylinder length="0.06" radius="0.01"/>
      </geometry>
    </visual>
  </link>

  <joint name="motor_right_joint" type="fixed">
    <origin rpy="0 0 0" xyz="0 -0.06 -0.03"/>
    <child link="motor_right_link"/>
    <parent link="base_link"/>
  </joint>

  <link name="motor_right_link">.005
    <inertial>.005
      <mass value="0.3"/>.005
      <origin rpy="0 1.5707 1.5707" xyz="0 0 0"/>
      <inertia ixx="9.75e-5" ixy="0.0" ixz="0.0"
               iyy="9.75e-5" iyz="0.0"
               izz="1.5e-5" />
    </inertial>

    <collision>
      <origin rpy="0 1.5707 1.5707" xyz="0 0 0"/>
      <geometry>
          <cylinder length="0.06" radius="0.01"/>
      </geometry>
    </collision>

    <visual>
      <origin rpy="0 1.5707 1.5707" xyz="0 0 0"/>
      <geometry>
        <cylinder length="0.06" radius="0.01"/>
      </geometry>
    </visual>
  </link>

<!-- Roller -->
  <joint name="caster_joint" type="fixed">
    <parent link="base_link"/>
    <child link="caster_link"/>
    <origin rpy="0 0 -0.075" xyz="-0.09 0.005 -0.044"/>
  </joint>

  <link name="caster_link">
    <collision>
      <origin rpy=" 0 0 0" xyz="0 0 0"/>
      <geometry>
        <sphere radius="0.015"/>
      </geometry>
      <surface>
        <friction>
          <ode>
            <mu>0</mu>
            <mu2>0</mu2>
            <slip1>1.0</slip1>
            <slip2>1.0</slip2>
          </ode>
        </friction>
      </surface>
    </collision>

    <inertial>
      <origin rpy="0 0 0" xyz="0 0 0"/>
      <mass value="0.05" />
      <inertia ixx="4.5e-06" ixy="0.0" ixz="0.0"
               iyy="4.5e-06" iyz="0.0"
               izz="4.5e-06" />
    </inertial>

    <visual>
      <origin rpy=" 0 0 -0.05" xyz="0.015 0 -0.005"/>
      <geometry>
        <mesh filename="package://vcr_description/meshes/wheels/roller.dae" scale="0.9 0.9 0.9"/>  
      </geometry>
    </visual>
  </link>

  <joint name="pin_joint" type="fixed">
       <origin rpy="0 0 0" xyz="-0.095 0 -0.0075"/>
       <child link="pin_link" />
       <parent link="base_link" />
  </joint>

  <link name="pin_link">
    <pose> 0 0 0 0 0 0</pose>
    <inertial>
      <mass value="0.6"/>
      <origin rpy="0 0 0" xyz="0 0 0"/>
      <inertia ixx="1.45e-4" ixy="0.0" ixz="0.0"
               iyy="1.45e-4" iyz="0.0"
               izz="1.45e-4" />
    <!-- <inertia ixx="0.05" ixy="0.0" ixz="0.0" iyy="0.05" iyz="0.0" izz="0.05"/> -->
    </inertial>

    <collision name="pin_collision">
      <origin rpy=" 0 0 0" xyz="0 0 0"/>
      <geometry>
        <box size="0.05 0.05 0.02"/>
      </geometry>
    </collision>

    <visual name="pin_visual">
      <origin rpy=" 0 0 0" xyz="0 0 0"/>
      <geometry>
        <box size="0.05 0.05 0.02"/>
      </geometry>
    </visual>
  </link>

<!-- Lidar -->
  <joint name="rplidar_joint" type="fixed">
    <axis xyz="0 1 0"/>
    <origin rpy="0 0 0" xyz="0.11 0 0"/>
    <child link="base_scan"/>
    <parent link="base_link"/>
  </joint>
  
  <link name="base_scan">
    <collision>
      <origin xyz="0 0 0" rpy="0 0 0"/>
      <geometry>
        <mesh filename="package://vcr_description/meshes/sensors/rplidar.dae" scale="1 1 1" />
      </geometry>
    </collision>

    <visual>
      <origin xyz="-0.05 0 0.015" rpy="0 0 0"/>
      <geometry>
        <!--box size="0.1 0.1 0.1"/-->
        <mesh filename="package://vcr_description/meshes/sensors/rplidar.dae" scale="1 1 1" />
      </geometry>			
    </visual>

    <inertial>
      <mass value="1e-5"/>
      <origin xyz="0 0 0" rpy="0 0 0"/>
      <inertia ixx="1e-6" ixy="0" ixz="0" iyy="1e-6" iyz="0" izz="1e-6"/>
    </inertial>
  </link>
  

  <!-- Camera -->
  <joint name="camera_joint" type="fixed">
    <axis xyz="0 1 0"/>
    <origin rpy="0 0 0" xyz="0.1 0 0.093"/>
    <child link="camera_link"/>
    <parent link="base_link"/>
  </joint>
  
  <link name="camera_link">
    <collision>
      <origin xyz="0 0 0" rpy="0 0 0"/>
      <geometry>
        <mesh filename="package://vcr_description/meshes/sensors/LogitechC270.stl" scale="0.001 0.001 0.001" />
      </geometry>
    </collision>

    <visual>
      <origin xyz="-0.05 0 0.045" rpy="0 0 1.5707"/>
      <geometry>
        <mesh filename="package://vcr_description/meshes/sensors/LogitechC270.stl" scale="0.001 0.001 0.001" />
      </geometry>			
    </visual>

    <inertial>
      <mass value="1e-5"/>
      <origin xyz="0 0 0" rpy="0 0 0"/>
      <inertia ixx="1e-6" ixy="0" ixz="0" iyy="1e-6" iyz="0" izz="1e-6"/>
    </inertial>
  </link>

</robot>
